Workbook

Sheet Aperçu
A1: Apercu des Notes EPC | E1: Acteurs territoriaux de Louga (Elus et SDE) | L1: Date: | M1: 42353 | O1: Note Standardisee | P1: Note Graduee
L2: Nbre. De Sondes: | N2: 37 | O2: 0 - 22 | P2: 5 | R2: Sondes
E3: Graduee | G3: Standardisee | O3: 23 - 32 | P3: 10 | R3: 37 | S3: Saint-Louis
E4: Note Cap | F4: Note Cons | G4: Note Cap | H4: Note Cons | O4: 33 - 39 | P4: 15 | R4: 45 | S4: Matam
A5: 1. Gestion des Ressources Humaines | E5: 40 | F5: 45 | G5: =GRH!A4 -> 62.358974 | H5: =GRH!A5 -> 66.08415 | I5: GRH | J5: Interpretation de la note Standardise: | O5: 40 - 45 | P5: 20 | R5: 38 | S5: Louga
A6: 2. Gestion des Ressources Financieres | E6: 40 | F6: 55 | G6: =GRF!A4 -> 62.377622 | H6: =GRF!A5 -> 74.12115 | I6: GRF | O6: 46 - 50 | P6: 25
A7: 3. Participation Equitable | E7: 50 | F7: 45 | G7: =PartEq!A4 -> 67.820513 | H7: =PartEq!A5 -> 65.331238 | I7: PartEq | J7: 20-39 | K7: loin en dessous de la moyenne / Niveau accceptable | O7: 51 - 55 | P7: 30 | R7: =SUM(R3:R6) -> 120 | S7: Total
A8: 4. Durabilite (Perennisation) des Acquis du Programme | E8: 50 | F8: 40 | G8: =Dur!A4 -> 68.333333 | H8: =Dur!A5 -> 61.887715 | I8: Dur | J8: 40-59 | K8: En dessous de la moyenne / Niveau acceptable | O8: 56 - 59 | P8: 35
A9: 5. Partenariat | E9: 50 | F9: 60 | G9: =Partn!A4 -> 68.531469 | H9: =Partn!A5 -> 74.934191 | I9: Partn | J9: 60-70 | K9: Moyen / niveau acceptable | O9: 60 - 63 | P9: 40
A10: 6. Gouvernance / Gestion Strategique | E10: 60 | F10: 60 | G10: =Gouv!A4 -> 75.076923 | H10: =Gouv!A5 -> 76.141442 | I10: Gouv | J10: 71-80 | K10: Au dessus de la moyenne / niveau acceptable | O10: 64 - 67 | P10: 45
J11: 81-100 | K11: Bien au dessus de la moyenne / Niveau acceptable | O11: 68 - 71 | P11: 50
D12: Moyenne | E12: =SUM(E5:E10)/6 -> 48.333333 | F12: =SUM(F5:F10)/6 -> 50.833333 | G12: =SUM(G5:G10)/6 -> 67.416472 | H12: =SUM(H5:H10)/6 -> 69.749981 | I12: Moyen | O12: 72 - 74 | P12: 55
O13: 75 - 78 | P13: 60
O14: 79 - 81 | P14: 65
O15: 82 - 84 | P15: 70
O16: 85 - 87 | P16: 75
O17: 88 - 89 | P17: 80
O18: 90- 92 | P18: 85
O19: 93 - 95 | P19: 90
O20: 96 - 98 | P20: 95
O21: 99 - 100 | P21: 100
A36: Moyens de la Cohorte
A37: Graduee
A38: Note Cap | B38: Note Cons
A39: =E5 -> 40 | B39: =F5 -> 45 | C39: GRH
A40: =E6 -> 40 | B40: =F6 -> 55 | C40: GRF
A41: =E7 -> 50 | B41: =F7 -> 45 | C41: PartEq
A42: =E8 -> 50 | B42: =F8 -> 40 | C42: Dur
A43: =E9 -> 50 | B43: =F9 -> 60 | C43: Partn
A44: =E10 -> 60 | B44: =F10 -> 60 | C44: Gouv
A45: =SUM(A39:A44)/6 -> 48.333333 | B45: =SUM(B39:B44)/6 -> 50.833333 | C45: Moyen

Sheet GRH
A1: Gestion des Ressources Humaines
L2: (Calculs) | W2: Interpretation de la Note Standardisee:
B3: Standardisee | L3: Nbre de Sondes | P3: =V27*V27 -> 369664 | Q3: y* | W3: 20-39 | X3: Loin en dessous de la moyenne / niveau acceptable
A4: =(P8/L6)*100 -> 62.358974 | B4: Note de Capacite | L4: 13 | P4: =L4*(L4-1) -> 156 | Q4: n* | W4: 40-59 | X4: Au dessus de la moyenne / niveau acceptable
A5: =100-(P9*2) -> 66.08415 | B5: Note de Consensus | L5: Points Max | P5: =(L4*V28)-P3 -> 16150 | Q5: m | W5: 60-70 | X5: Moyen / niveau acceptable
L6: =A26*5 -> 75 | P6: =P5/P4 -> 103.52564 | Q6: p | W6: 71-80 | X6: Au dessus de la moyenne / niveau acceptable
L7: Nbre de Questions | P7: =SQRT(P6) -> 10.174755 | Q7: SD | W7: 81-100 | X7: Loin au-dessus de la moyenne / niveau acceptable
L8: =A26 -> 15 | P8: =V27/L4 -> 46.769231 | Q8: Note brute de Cap
P9: =P7/((L8*5)-(L8*1))*100 -> 16.957925 | Q9: Note brute de Consensus
B10: Sondes | F10: 5 | K10: 10 | P10: 15 | U10: 20 | W10: Note Standardisee Par Element
A11: Elements | B11: a | C11: b | D11: c | E11: d | F11: e | G11: f | H11: g | I11: h | J11: i | K11: j | L11: k | M11: l | N11: m | O11: n | P11: o | Q11: p | R11: q | S11: r | T11: s | U11: t | V11: Somme | W11: Note Cap | X11: Note Cons | Y11: Elements
A12: 1 | B12: 4 | C12: 4 | D12: 2 | E12: 3 | F12: 4 | G12: 4 | H12: 5 | I12: 3 | J12: 2 | K12: 2 | L12: 2 | M12: 2 | N12: 2 | V12: =SUM(B12:U12) -> 39 | W12: =V12/L4*20 -> 60 | X12: =100-(AB44*2) -> 45.993828 | Y12: 1. Recrutement transparent
A13: 2 | B13: 4 | C13: 4 | D13: 3 | E13: 4 | F13: 3 | G13: 4 | H13: 3 | I13: 1 | J13: 3 | K13: 3 | L13: 3 | M13: 4 | N13: 4 | V13: =SUM(B13:U13) -> 43 | W13: =V13/L4*20 -> 66.153846 | X13: =100-(AB45*2) -> 57.257479 | Y13: 2. Transdisciplinarité
A14: 3 | B14: 5 | C14: 5 | D14: 2 | E14: 3 | F14: 3 | G14: 3 | H14: 5 | I14: 1 | J14: 3 | K14: 2 | L14: 1 | M14: 1 | N14: 4 | V14: =SUM(B14:U14) -> 38 | W14: =V14/L4*20 -> 58.461538 | X14: =100-(AB46*2) -> 25.106914 | Y14: 3. Egalité de genre
A15: 4 | B15: 5 | C15: 3 | D15: 2 | E15: 3 | F15: 4 | G15: 2 | H15: 5 | I15: 5 | J15: 3 | K15: 4 | L15: 3 | M15: 2 | N15: 4 | V15: =SUM(B15:U15) -> 45 | W15: =V15/L4*20 -> 69.230769 | X15: =100-(AB47*2) -> 43.669929 | Y15: 4. Parité H/F
A16: 5 | B16: 4 | C16: 4 | D16: 2 | E16: 2 | F16: 3 | G16: 4 | H16: 4 | I16: 4 | J16: 2 | K16: 2 | L16: 2 | M16: 2 | N16: 2 | V16: =SUM(B16:U16) -> 37 | W16: =V16/L4*20 -> 56.923077 | X16: =100-(AB48*2) -> 50.645188 | Y16: 5. Diversité du personnel
A17: 6 | B17: 5 | C17: 4 | D17: 5 | E17: 2 | F17: 4 | G17: 4 | H17: 5 | I17: 5 | J17: 2 | K17: 4 | L17: 1 | M17: 2 | N17: 2 | V17: =SUM(B17:U17) -> 45 | W17: =V17/L4*20 -> 69.230769 | X17: =100-(AB49*2) -> 27.498895 | Y17: 6. Profil du personnel
A18: 7 | B18: 5 | C18: 2 | D18: 4 | E18: 4 | F18: 3 | G18: 4 | H18: 4 | I18: 4 | J18: 2 | K18: 3 | L18: 2 | M18: 2 | N18: 4 | V18: =SUM(B18:U18) -> 43 | W18: =V18/L4*20 -> 66.153846 | X18: =100-(AB50*2) -> 48.422326 | Y18: 7. Compétences du personnel
A19: 8 | B19: 3 | C19: 4 | D19: 2 | E19: 3 | F19: 1 | G19: 4 | H19: 2 | I19: 3 | J19: 2 | K19: 1 | L19: 2 | M19: 2 | N19: 4 | V19: =SUM(B19:U19) -> 33 | W19: =V19/L4*20 -> 50.769231 | X19: =100-(AB51*2) -> 47.498474 | Y19: 8. Effectif du personnel
A20: 9 | B20: 3 | C20: 3 | D20: 3 | E20: 2 | F20: 1 | G20: 4 | H20: 4 | I20: 4 | J20: 2 | K20: 4 | L20: 1 | M20: 2 | N20: 4 | V20: =SUM(B20:U20) -> 37 | W20: =V20/L4*20 -> 56.923077 | X20: =100-(AB52*2) -> 42.822813 | Y20: 9. Formations régulières
A21: 10 | B21: 4 | C21: 4 | D21: 5 | E21: 4 | F21: 3 | G21: 5 | H21: 5 | I21: 5 | J21: 4 | K21: 4 | L21: 3 | M21: 2 | N21: 2 | V21: =SUM(B21:U21) -> 50 | W21: =V21/L4*20 -> 76.923077 | X21: =100-(AB53*2) -> 46.590599 | Y21: 10. Formations adaptées
A22: 11 | B22: 3 | C22: 4 | D22: 5 | E22: 4 | F22: 3 | G22: 4 | H22: 5 | I22: 4 | J22: 4 | K22: 2 | L22: 3 | M22: 2 | N22: 2 | V22: =SUM(B22:U22) -> 45 | W22: =V22/L4*20 -> 69.230769 | X22: =100-(AB54*2) -> 47.498474 | Y22: 11. Formation selon priorités
A23: 12 | B23: 3 | C23: 4 | D23: 5 | E23: 3 | F23: 2 | G23: 2 | H23: 1 | I23: 5 | J23: 3 | K23: 3 | L23: 1 | M23: 2 | N23: 2 | V23: =SUM(B23:U23) -> 36 | W23: =V25/L4*20 -> 70.769231 | X23: =100-(AB55*2) -> 34.955636 | Y23: 12. Motivation
A24: 13 | B24: 4 | C24: 3 | D24: 1 | E24: 3 | F24: 3 | G24: 4 | H24: 4 | I24: 4 | J24: 3 | K24: 2 | L24: 3 | M24: 2 | N24: 2 | V24: =SUM(B24:U24) -> 38 | W24: =V26/L4*20 -> 50.769231 | X24: =100-(AB56*2) -> 52.296321 | Y24: 13. Gestion des conflits
A25: 14 | B25: 4 | C25: 5 | D25: 5 | E25: 4 | F25: 3 | G25: 4 | H25: 5 | I25: 4 | J25: 2 | K25: 3 | L25: 3 | M25: 2 | N25: 2 | V25: =SUM(B25:U25) -> 46 | W25: =V27/L4*20 -> 935.38462 | X25: =100-(AB57*2) -> 28.86379 | Y25: 14. Supervision
A26: 15 | B26: 3 | C26: 4 | D26: 1 | E26: 3 | F26: 3 | G26: 3 | H26: 3 | I26: 5 | J26: 2 | K26: 1 | L26: 1 | M26: 2 | N26: 2 | V26: =SUM(B26:U26) -> 33 | W26: =V28/L4*20 -> 45658.462 | X26: =100-(AB58*2) -> 45.947973 | Y26: 15. Evaluation
A27: x | B27: =SUM(B12:B26) -> 59 | C27: =SUM(C12:C26) -> 57 | D27: =SUM(D12:D26) -> 47 | E27: =SUM(E12:E26) -> 47 | F27: =SUM(F12:F26) -> 43 | G27: =SUM(G12:G26) -> 55 | H27: =SUM(H12:H26) -> 60 | I27: =SUM(I12:I26) -> 57 | ... U27: =SUM(U12:U26) -> 0 | V27: =SUM(B27:U27) -> 608
A28: x2 | B28: =B27*B27 -> 3481 | C28: =C27*C27 -> 3249 | D28: =D27*D27 -> 2209 | E28: =E27*E27 -> 2209 | F28: =F27*F27 -> 1849 | G28: =G27*G27 -> 3025 | H28: =H27*H27 -> 3600 | I28: =I27*I27 -> 3249 | ... U28: =U27*U27 -> 0 | V28: =SUM(B28:U28) -> 29678
A42: Fiche de calcul pour une note distincte de capacite (x2)
A43: Element | B43: a | C43: b | D43: c | E43: d | F43: e | G43: f | H43: g | I43: h | J43: i | K43: j | L43: k | M43: l | N43: m | O43: n | P43: o | Q43: p | R43: q | S43: r | T43: s | U43: t | V43: Som x2 | W43: y* | X43: n* | Y43: m | Z43: p | AA43: sd | AB43: raw
A44: 1 | B44: =B12*B12 -> 16 | C44: =C12*C12 -> 16 | D44: =D12*D12 -> 4 | E44: =E12*E12 -> 9 | F44: =F12*F12 -> 16 | G44: =G12*G12 -> 16 | H44: =H12*H12 -> 25 | I44: =I12*I12 -> 9 | ... Q44: =Q12*Q12 -> 0 | V44: =SUM(B44:U44) -> 131 | W44: =V12*V12 -> 1521 | X44: =L4*(L4-1) -> 156 | Y44: =L4*V44-W44 -> 182 | Z44: =Y44/X44 -> 1.1666667 | AA44: =SQRT(Z44) -> 1.0801234 | AB44: =AA44/4*100 -> 27.003086
A45: 2 | B45: =B13*B13 -> 16 | C45: =C13*C13 -> 16 | D45: =D13*D13 -> 9 | E45: =E13*E13 -> 16 | F45: =F13*F13 -> 9 | G45: =G13*G13 -> 16 | H45: =H13*H13 -> 9 | I45: =I13*I13 -> 1 | ... Q45: =Q13*Q13 -> 0 | V45: =SUM(B45:U45) -> 151 | W45: =V13*V13 -> 1849 | X45: =L4*(L4-1) -> 156 | Y45: =L4*V45-W45 -> 114 | Z45: =Y45/X45 -> 0.73076923 | AA45: =SQRT(Z45) -> 0.85485041 | AB45: =AA45/4*100 -> 21.37126
A46: 3 | B46: =B14*B14 -> 25 | C46: =C14*C14 -> 25 | D46: =D14*D14 -> 4 | E46: =E14*E14 -> 9 | F46: =F14*F14 -> 9 | G46: =G14*G14 -> 9 | H46: =H14*H14 -> 25 | I46: =I14*I14 -> 1 | ... Q46: =Q14*Q14 -> 0 | V46: =SUM(B46:U46) -> 138 | W46: =V14*V14 -> 1444 | X46: =L4*(L4-1) -> 156 | Y46: =L4*V46-W46 -> 350 | Z46: =Y46/X46 -> 2.2435897 | AA46: =SQRT(Z46) -> 1.4978617 | AB46: =AA46/4*100 -> 37.446543
A47: 4 | B47: =B15*B15 -> 25 | C47: =C15*C15 -> 9 | D47: =D15*D15 -> 4 | E47: =E15*E15 -> 9 | F47: =F15*F15 -> 16 | G47: =G15*G15 -> 4 | H47: =H15*H15 -> 25 | I47: =I15*I15 -> 25 | ... Q47: =Q15*Q15 -> 0 | V47: =SUM(B47:U47) -> 171 | W47: =V15*V15 -> 2025 | X47: =L4*(L4-1) -> 156 | Y47: =L4*V47-W47 -> 198 | Z47: =Y47/X47 -> 1.2692308 | AA47: =SQRT(Z47) -> 1.1266014 | AB47: =AA47/4*100 -> 28.165036
A48: 5 | B48: =B16*B16 -> 16 | C48: =C16*C16 -> 16 | D48: =D16*D16 -> 4 | E48: =E16*E16 -> 4 | F48: =F16*F16 -> 9 | G48: =G16*G16 -> 16 | H48: =H16*H16 -> 16 | I48: =I16*I16 -> 16 | ... Q48: =Q16*Q16 -> 0 | V48: =SUM(B48:U48) -> 117 | W48: =V16*V16 -> 1369 | X48: =L4*(L4-1) -> 156 | Y48: =L4*V48-W48 -> 152 | Z48: =Y48/X48 -> 0.97435897 | AA48: =SQRT(Z48) -> 0.98709623 | AB48: =AA48/4*100 -> 24.677406
A49: 6 | B49: =B17*B17 -> 25 | C49: =C17*C17 -> 16 | D49: =D17*D17 -> 25 | E49: =E17*E17 -> 4 | F49: =F17*F17 -> 16 | G49: =G17*G17 -> 16 | H49: =H17*H17 -> 25 | I49: =I17*I17 -> 25 | ... Q49: =Q17*Q17 -> 0 | V49: =SUM(B49:U49) -> 181 | W49: =V17*V17 -> 2025 | X49: =L4*(L4-1) -> 156 | Y49: =L4*V49-W49 -> 328 | Z49: =Y49/X49 -> 2.1025641 | AA49: =SQRT(Z49) -> 1.4500221 | AB49: =AA49/4*100 -> 36.250553
A50: 7 | B50: =B18*B18 -> 25 | C50: =C18*C18 -> 4 | D50: =D18*D18 -> 16 | E50: =E18*E18 -> 16 | F50: =F18*F18 -> 9 | G50: =G18*G18 -> 16 | H50: =H18*H18 -> 16 | I50: =I18*I18 -> 16 | ... Q50: =Q18*Q18 -> 0 | V50: =SUM(B50:U50) -> 155 | W50: =V18*V18 -> 1849 | X50: =L4*(L4-1) -> 156 | Y50: =L4*V50-W50 -> 166 | Z50: =Y50/X50 -> 1.0641026 | AA50: =SQRT(Z50) -> 1.0315535 | AB50: =AA50/4*100 -> 25.788837
A51: 8 | B51: =B19*B19 -> 9 | C51: =C19*C19 -> 16 | D51: =D19*D19 -> 4 | E51: =E19*E19 -> 9 | F51: =F19*F19 -> 1 | G51: =G19*G19 -> 16 | H51: =H19*H19 -> 4 | I51: =I19*I19 -> 9 | ... Q51: =Q19*Q19 -> 0 | V51: =SUM(B51:U51) -> 97 | W51: =V19*V19 -> 1089 | X51: =L4*(L4-1) -> 156 | Y51: =L4*V51-W51 -> 172 | Z51: =Y51/X51 -> 1.1025641 | AA51: =SQRT(Z51) -> 1.0500305 | AB51: =AA51/4*100 -> 26.250763
A52: 9 | B52: =B20*B20 -> 9 | C52: =C20*C20 -> 9 | D52: =D20*D20 -> 9 | E52: =E20*E20 -> 4 | F52: =F20*F20 -> 1 | G52: =G20*G20 -> 16 | H52: =H20*H20 -> 16 | I52: =I20*I20 -> 16 | ... Q52: =Q20*Q20 -> 0 | V52: =SUM(B52:U52) -> 121 | W52: =V20*V20 -> 1369 | X52: =L4*(L4-1) -> 156 | Y52: =L4*V52-W52 -> 204 | Z52: =Y52/X52 -> 1.3076923 | AA52: =SQRT(Z52) -> 1.1435437 | AB52: =AA52/4*100 -> 28.588594
A53: 10 | B53: =B21*B21 -> 16 | C53: =C21*C21 -> 16 | D53: =D21*D21 -> 25 | E53: =E21*E21 -> 16 | F53: =F21*F21 -> 9 | G53: =G21*G21 -> 25 | H53: =H21*H21 -> 25 | I53: =I21*I21 -> 25 | ... Q53: =Q21*Q21 -> 0 | V53: =SUM(B53:U53) -> 206 | W53: =V21*V21 -> 2500 | X53: =L4*(L4-1) -> 156 | Y53: =L4*V53-W53 -> 178 | Z53: =Y53/X53 -> 1.1410256 | AA53: =SQRT(Z53) -> 1.068188 | AB53: =AA53/4*100 -> 26.7047
...

Sheet GRF
A1: Gestion des Ressources Financieres
L2: (Calculs) | W2: Interpretation de la Note Standardisee:
B3: Standardisee | L3: Nbre de Sondes | P3: =V25*V25 -> 198916 | Q3: y* | W3: 20-39 | X3: Loin en dessous de la moyenne / niveau acceptable
A4: =(P8/L6)*100 -> 62.377622 | B4: Note Capacite | L4: 11 | P4: =L4*(L4-1) -> 110 | Q4: n* | W4: 40-59 | X4: Au dessus de la moyenne / niveau acceptable
A5: =100-(P9*2) -> 74.12115 | B5: Note Consensus | L5: Points Max | P5: =(L4*V26)-P3 -> 4980 | Q5: m | W5: 60-70 | X5: Moyen / niveau acceptable
L6: =A24*5 -> 65 | P6: =P5/P4 -> 45.272727 | Q6: p | W6: 71-80 | X6: Au dessus de la moyenne / niveau acceptable
L7: Nbre de Questions | P7: =SQRT(P6) -> 6.7285011 | Q7: SD | W7: 81-100 | X7: Loin au-dessus de la moyenne / niveau acceptable
L8: 13 | P8: =V25/L4 -> 40.545455 | Q8: Note Brute Cap
P9: =P7/((L8*5)-(L8*1))*100 -> 12.939425 | Q9: Note brute Cons
B10: Sondes | F10: 5 | K10: 10 | P10: 15 | U10: 20 | W10: Note Standardisee Par Element
A11: Elements | B11: a | C11: b | D11: c | E11: d | F11: e | G11: f | H11: g | I11: h | J11: i | K11: j | L11: k | M11: l | N11: m | O11: n | P11: o | Q11: p | R11: q | S11: r | T11: s | U11: t | V11: Sum | W11: Note Cap | X11: Note Cons | Y11: Elements
A12: 1 | B12: 4 | C12: 5 | D12: 4 | E12: 5 | F12: 2 | G12: 5 | H12: 5 | I12: 5 | J12: 3 | K12: 3 | L12: 3 | V12: =SUM(B12:U12) -> 44 | W12: =V12/L4*20 -> 80 | X12: =100-(AB38*2) -> 45.227744 | Y12: 1. Procédures régulières
A13: 2 | B13: 4 | C13: 5 | D13: 4 | E13: 5 | F13: 4 | G13: 5 | H13: 5 | I13: 4 | J13: 3 | K13: 2 | L13: 4 | V13: =SUM(B13:U13) -> 45 | W13: =V13/L4*20 -> 81.818182 | X13: =100-(AB39*2) -> 52.80601 | Y13: 2. Budgétisation selon priorités
A14: 3 | B14: 2 | C14: 2 | D14: 4 | E14: 4 | F14: 4 | G14: 1 | H14: 3 | I14: 2 | J14: 4 | K14: 1 | L14: 2 | V14: =SUM(B14:U14) -> 29 | W14: =V14/L4*20 -> 52.727273 | X14: =100-(AB40*2) -> 39.697731 | Y14: 3. Prévisions financières
A15: 4 | B15: 4 | C15: 4 | D15: 5 | E15: 4 | F15: 4 | G15: 5 | H15: 3 | I15: 2 | J15: 3 | K15: 2 | L15: 2 | V15: =SUM(B15:U15) -> 38 | W15: =V15/L4*20 -> 69.090909 | X15: =100-(AB41*2) -> 43.592393 | Y15: 4. Dépenses selon revenus
A16: 5 | B16: 2 | C16: 4 | D16: 4 | E16: 4 | F16: 4 | G16: 4 | H16: 5 | I16: 5 | J16: 3 | K16: 4 | L16: 2 | V16: =SUM(B16:U16) -> 41 | W16: =V16/L4*20 -> 74.545455 | X16: =100-(AB42*2) -> 49.547502 | Y16: 5. Charges fixes
A17: 6 | B17: 4 | C17: 4 | D17: 4 | E17: 4 | F17: 4 | G17: 4 | H17: 3 | I17: 3 | J17: 3 | K17: 3 | L17: 2 | V17: =SUM(B17:U17) -> 38 | W17: =V17/L4*20 -> 69.090909 | X17: =100-(AB43*2) -> 65.622417 | Y17: 6. Décaissements périodiques
A18: 7 | B18: 2 | C18: 2 | D18: 2 | E18: 2 | F18: 2 | G18: 1 | H18: 2 | I18: 2 | J18: 2 | K18: 2 | L18: 2 | V18: =SUM(B18:U18) -> 21 | W18: =V18/L4*20 -> 38.181818 | X18: =100-(AB44*2) -> 84.924433 | Y18: 7. Appui de l’Etat
A19: 8 | B19: 2 | C19: 2 | D19: 2 | E19: 3 | F19: 2 | G19: 2 | H19: 2 | I19: 2 | J19: 2 | K19: 2 | L19: 2 | V19: =SUM(B19:U19) -> 23 | W19: =V19/L4*20 -> 41.818182 | X19: =100-(AB45*2) -> 84.924433 | Y19: 8. Appui des Partenaires
A20: 9 | B20: 2 | C20: 2 | D20: 4 | E20: 4 | F20: 4 | G20: 4 | H20: 2 | I20: 2 | J20: 2 | K20: 2 | L20: 2 | V20: =SUM(B20:U20) -> 30 | W20: =V20/L4*20 -> 54.545455 | X20: =100-(AB46*2) -> 49.547502 | Y20: 9. Ressources pour activités
A21: 10 | B21: 2 | C21: 4 | D21: 4 | E21: 4 | F21: 4 | G21: 4 | H21: 2 | I21: 2 | J21: 3 | K21: 2 | L21: 2 | V21: =SUM(B21:U21) -> 33 | W21: =V21/L4*20 -> 60 | X21: =100-(AB47*2) -> 50 | Y21: 10. Ressources pour infrastructures
A22: 11 | B22: 2 | C22: 4 | D22: 4 | E22: 4 | F22: 4 | G22: 4 | H22: 4 | I22: 4 | J22: 3 | K22: 2 | L22: 4 | V22: =SUM(B22:U22) -> 39 | W22: =V22/L4*20 -> 70.909091 | X22: =100-(AB48*2) -> 58.990023 | Y22: 11. Ressources pour communication
A23: 12 | B23: 5 | C23: 2 | D23: 4 | E23: 3 | F23: 4 | G23: 5 | H23: 2 | I23: 2 | J23: 2 | K23: 2 | L23: 2 | V23: =SUM(B23:U23) -> 33 | W23: =V23/L4*20 -> 60 | X23: =100-(AB49*2) -> 36.754447 | Y23: 12. Ressources internes
A24: 13 | B24: 5 | C24: 2 | D24: 3 | E24: 3 | F24: 2 | G24: 5 | H24: 2 | I24: 2 | J24: 3 | K24: 2 | L24: 3 | V24: =SUM(B24:U24) -> 32 | W24: =V24/L4*20 -> 58.181818 | X24: =100-(AB50*2) -> 100 | Y24: 13. Ressources externes
A25: x | B25: =SUM(B12:B24) -> 40 | C25: =SUM(C12:C24) -> 42 | D25: =SUM(D12:D24) -> 48 | E25: =SUM(E12:E24) -> 49 | F25: =SUM(F12:F24) -> 44 | G25: =SUM(G12:G24) -> 49 | H25: =SUM(H12:H24) -> 40 | I25: =SUM(I12:I24) -> 37 | ... U25: =SUM(U12:U24) -> 0 | V25: =SUM(B25:U25) -> 446
A26: x2 | B26: =B25*B25 -> 1600 | C26: =C25*C25 -> 1764 | D26: =D25*D25 -> 2304 | E26: =E25*E25 -> 2401 | F26: =F25*F25 -> 1936 | G26: =G25*G25 -> 2401 | H26: =H25*H25 -> 1600 | I26: =I25*I25 -> 1369 | ... U26: =U25*U25 -> 0 | V26: =SUM(B26:U26) -> 18536
W27: z*
A35: Fiche de calcul pour une note distincte de capacite (x2)
A36: Element | B36: a | C36: b | D36: c | E36: d | F36: e | G36: f | H36: g | I36: h | J36: i | K36: j | L36: k | M36: l | N36: m | O36: n | P36: o | Q36: p | R36: q | S36: r | T36: s | U36: t | V36: Som x2
A37: 1 | B37: =B12*B12 -> 16 | C37: =C12*C12 -> 25 | D37: =D12*D12 -> 16 | E37: =E12*E12 -> 25 | F37: =F12*F12 -> 4 | G37: =G12*G12 -> 25 | H37: =H12*H12 -> 25 | I37: =I12*I12 -> 25 | ... U37: =U12*U12 -> 0 | V37: =SUM(B37:U37) -> 188 | W37: y* | X37: n* | Y37: m | Z37: p | AA37: sd | AB37: brute
A38: 2 | B38: =B13*B13 -> 16 | C38: =C13*C13 -> 25 | D38: =D13*D13 -> 16 | E38: =E13*E13 -> 25 | F38: =F13*F13 -> 16 | G38: =G13*G13 -> 25 | H38: =H13*H13 -> 25 | I38: =I13*I13 -> 16 | ... U38: =U13*U13 -> 0 | V38: =SUM(B38:U38) -> 193 | W38: =V12*V12 -> 1936 | X38: =L4*(L4-1) -> 110 | Y38: =L4*V37-W38 -> 132 | Z38: =Y38/X38 -> 1.2 | AA38: =SQRT(Z38) -> 1.0954451 | AB38: =AA38/4*100 -> 27.386128
A39: 3 | B39: =B14*B14 -> 4 | C39: =C14*C14 -> 4 | D39: =D14*D14 -> 16 | E39: =E14*E14 -> 16 | F39: =F14*F14 -> 16 | G39: =G14*G14 -> 1 | H39: =H14*H14 -> 9 | I39: =I14*I14 -> 4 | ... U39: =U14*U14 -> 0 | V39: =SUM(B39:U39) -> 91 | W39: =V13*V13 -> 2025 | X39: =L4*(L4-1) -> 110 | Y39: =L4*V38-W39 -> 98 | Z39: =Y39/X39 -> 0.89090909 | AA39: =SQRT(Z39) -> 0.94387981 | AB39: =AA39/4*100 -> 23.596995
A40: 4 | B40: =B15*B15 -> 16 | C40: =C15*C15 -> 16 | D40: =D15*D15 -> 25 | E40: =E15*E15 -> 16 | F40: =F15*F15 -> 16 | G40: =G15*G15 -> 25 | H40: =H15*H15 -> 9 | I40: =I15*I15 -> 4 | ... U40: =U15*U15 -> 0 | V40: =SUM(B40:U40) -> 144 | W40: =V14*V14 -> 841 | X40: =L4*(L4-1) -> 110 | Y40: =L4*V39-W40 -> 160 | Z40: =Y40/X40 -> 1.4545455 | AA40: =SQRT(Z40) -> 1.2060454 | AB40: =AA40/4*100 -> 30.151134
A41: 5 | B41: =B16*B16 -> 4 | C41: =C16*C16 -> 16 | D41: =D16*D16 -> 16 | E41: =E16*E16 -> 16 | F41: =F16*F16 -> 16 | G41: =G16*G16 -> 16 | H41: =H16*H16 -> 25 | I41: =I16*I16 -> 25 | ... U41: =U16*U16 -> 0 | V41: =SUM(B41:U41) -> 163 | W41: =V15*V15 -> 1444 | X41: =L4*(L4-1) -> 110 | Y41: =L4*V40-W41 -> 140 | Z41: =Y41/X41 -> 1.2727273 | AA41: =SQRT(Z41) -> 1.1281521 | AB41: =AA41/4*100 -> 28.203804
A42: 6 | B42: =B17*B17 -> 16 | C42: =C17*C17 -> 16 | D42: =D17*D17 -> 16 | E42: =E17*E17 -> 16 | F42: =F17*F17 -> 16 | G42: =G17*G17 -> 16 | H42: =H17*H17 -> 9 | I42: =I17*I17 -> 9 | ... U42: =U17*U17 -> 0 | V42: =SUM(B42:U42) -> 136 | W42: =V16*V16 -> 1681 | X42: =L4*(L4-1) -> 110 | Y42: =L4*V41-W42 -> 112 | Z42: =Y42/X42 -> 1.0181818 | AA42: =SQRT(Z42) -> 1.00905 | AB42: =AA42/4*100 -> 25.226249
A43: 7 | B43: =B18*B18 -> 4 | C43: =C18*C18 -> 4 | D43: =D18*D18 -> 4 | E43: =E18*E18 -> 4 | F43: =F18*F18 -> 4 | G43: =G18*G18 -> 1 | H43: =H18*H18 -> 4 | I43: =I18*I18 -> 4 | ... U43: =U18*U18 -> 0 | V43: =SUM(B43:U43) -> 41 | W43: =V17*V17 -> 1444 | X43: =L4*(L4-1) -> 110 | Y43: =L4*V42-W43 -> 52 | Z43: =Y43/X43 -> 0.47272727 | AA43: =SQRT(Z43) -> 0.68755165 | AB43: =AA43/4*100 -> 17.188791
A44: 8 | B44: =B19*B19 -> 4 | C44: =C19*C19 -> 4 | D44: =D19*D19 -> 4 | E44: =E19*E19 -> 9 | F44: =F19*F19 -> 4 | G44: =G19*G19 -> 4 | H44: =H19*H19 -> 4 | I44: =I19*I19 -> 4 | ... U44: =U19*U19 -> 0 | V44: =SUM(B44:U44) -> 49 | W44: =V18*V18 -> 441 | X44: =L4*(L4-1) -> 110 | Y44: =L4*V43-W44 -> 10 | Z44: =Y44/X44 -> 0.090909091 | AA44: =SQRT(Z44) -> 0.30151134 | AB44: =AA44/4*100 -> 7.5377836
A45: 9 | B45: =B20*B20 -> 4 | C45: =C20*C20 -> 4 | D45: =D20*D20 -> 16 | E45: =E20*E20 -> 16 | F45: =F20*F20 -> 16 | G45: =G20*G20 -> 16 | H45: =H20*H20 -> 4 | I45: =I20*I20 -> 4 | ... U45: =U20*U20 -> 0 | V45: =SUM(B45:U45) -> 92 | W45: =V19*V19 -> 529 | X45: =L4*(L4-1) -> 110 | Y45: =L4*V44-W45 -> 10 | Z45: =Y45/X45 -> 0.090909091 | AA45: =SQRT(Z45) -> 0.30151134 | AB45: =AA45/4*100 -> 7.5377836
A46: 10 | B46: =B21*B21 -> 4 | C46: =C21*C21 -> 16 | D46: =D21*D21 -> 16 | E46: =E21*E21 -> 16 | F46: =F21*F21 -> 16 | G46: =G21*G21 -> 16 | H46: =H21*H21 -> 4 | I46: =I21*I21 -> 4 | ... U46: =U21*U21 -> 0 | V46: =SUM(B46:U46) -> 109 | W46: =V20*V20 -> 900 | X46: =L4*(L4-1) -> 110 | Y46: =L4*V45-W46 -> 112 | Z46: =Y46/X46 -> 1.0181818 | AA46: =SQRT(Z46) -> 1.00905 | AB46: =AA46/4*100 -> 25.226249
A47: 11 | B47: =B22*B22 -> 4 | C47: =C22*C22 -> 16 | D47: =D22*D22 -> 16 | E47: =E22*E22 -> 16 | F47: =F22*F22 -> 16 | G47: =G22*G22 -> 16 | H47: =H22*H22 -> 16 | I47: =I22*I22 -> 16 | ... U47: =U22*U22 -> 0 | V47: =SUM(B47:U47) -> 145 | W47: =V21*V21 -> 1089 | X47: =L4*(L4-1) -> 110 | Y47: =L4*V46-W47 -> 110 | Z47: =Y47/X47 -> 1 | AA47: =SQRT(Z47) -> 1 | AB47: =AA47/4*100 -> 25
...

Sheet PartEq
A1: Participation Equitable
L2: (Calculs) | W2: Interpretation de la Note Standardisee: | AC2: Sondes
B3: Standardisee | L3: Nbre de Sondes | P3: =V24*V24 -> 279841 | Q3: y* | W3: 20-39 | X3: Loin en dessous de la moyenne / niveau acceptable | AC3: 37 | AD3: Saint-Louis
A4: =(P8/L6)*100 -> 67.820513 | B4: Note Capacite | L4: 13 | P4: =L4*(L4-1) -> 156 | Q4: n* | W4: 40-59 | X4: Au dessus de la moyenne / niveau acceptable | AC4: 45 | AD4: Matam
A5: =100-(P9*2) -> 65.331238 | B5: Note Consensus | L5: Points Max | P5: =(L4*V25)-P3 -> 10800 | Q5: m | W5: 60-70 | X5: Moyen / niveau acceptable | AC5: 38 | AD5: Louga
L6: =A23*5 -> 60 | P6: =P5/P4 -> 69.230769 | Q6: p | W6: 71-80 | X6: Au dessus de la moyenne / niveau acceptable
L7: Nbre de Questions | P7: =SQRT(P6) -> 8.3205029 | Q7: SD | W7: 81-100 | X7: Loin au-dessus de la moyenne / niveau acceptable | AC7: =SUM(AC3:AC6) -> 120
L8: 12 | P8: =V24/L4 -> 40.692308 | Q8: Note Brute Cap
P9: =P7/((L8*5)-(L8*1))*100 -> 17.334381 | Q9: Note Brute Cons
B10: Sondes | F10: 5 | K10: 10 | P10: 15 | U10: 20 | W10: Notes Standardisees Par Element
A11: Element | B11: a | C11: b | D11: c | E11: d | F11: e | G11: f | H11: g | I11: h | J11: i | K11: j | L11: k | M11: l | N11: m | O11: n | P11: o | Q11: p | R11: q | S11: r | T11: s | U11: t | V11: Sum | W11: Note Cap | X11: Note Cons | Y11: Elements
A12: 1 | B12: 5 | C12: 4 | D12: 4 | E12: 4 | F12: 4 | G12: 4 | H12: 4 | I12: 4 | J12: 5 | K12: 4 | L12: 3 | M12: 2 | N12: 4 | V12: =SUM(B12:U12) -> 51 | W12: =V12/L4*20 -> 78.461538 | X12: =100-(AB41*2) -> 62.022274 | Y12: 1. Evaluation des besoins
A13: 2 | B13: 4 | C13: 4 | D13: 4 | E13: 5 | F13: 5 | G13: 4 | H13: 4 | I13: 5 | J13: 3 | K13: 4 | L13: 4 | M13: 4 | N13: 4 | V13: =SUM(B13:U13) -> 54 | W13: =V13/L4*20 -> 83.076923 | X13: =100-(AB42*2) -> 72.26499 | Y13: 2. Conception des projets
A14: 3 | B14: 4 | C14: 4 | D14: 3 | E14: 2 | F14: 4 | G14: 3 | H14: 2 | I14: 4 | J14: 2 | K14: 3 | L14: 2 | M14: 2 | N14: 2 | V14: =SUM(B14:U14) -> 37 | W14: =V14/L4*20 -> 56.923077 | X14: =100-(AB43*2) -> 55.064148 | Y14: 3. Suivi-évaluation des projets
A15: 4 | B15: 5 | C15: 2 | D15: 2 | E15: 4 | F15: 4 | G15: 4 | H15: 1 | I15: 4 | J15: 1 | K15: 3 | L15: 2 | M15: 2 | N15: 1 | V15: =SUM(B15:U15) -> 35 | W15: =V15/L4*20 -> 53.846154 | X15: =100-(AB44*2) -> 31.126277 | Y15: 4. Accès aux activités
A16: 5 | B16: 3 | C16: 2 | D16: 2 | E16: 4 | F16: 4 | G16: 3 | H16: 1 | I16: 4 | J16: 3 | K16: 3 | L16: 2 | M16: 1 | N16: 1 | V16: =SUM(B16:U16) -> 33 | W16: =V16/L4*20 -> 50.769231 | X16: =100-(AB45*2) -> 43.669929 | Y16: 5. Accès aux bénéfices
A17: 6 | B17: 5 | C17: 4 | D17: 4 | E17: 4 | F17: 3 | G17: 3 | H17: 2 | I17: 4 | J17: 2 | K17: 4 | L17: 2 | M17: 2 | N17: 2 | V17: =SUM(B17:U17) -> 41 | W17: =V17/L4*20 -> 63.076923 | X17: =100-(AB46*2) -> 46.590599 | Y17: 6. Equité dans la conception
A18: 7 | B18: 3 | C18: 4 | D18: 4 | E18: 5 | F18: 4 | G18: 3 | H18: 2 | I18: 5 | J18: 1 | K18: 4 | L18: 2 | M18: 2 | N18: 2 | V18: =SUM(B18:U18) -> 41 | W18: =V18/L4*20 -> 63.076923 | X18: =100-(AB47*2) -> 35.948738 | Y18: 7. Equité dans la mise en œuvre
A19: 8 | B19: 5 | C19: 2 | D19: 2 | E19: 4 | F19: 4 | G19: 4 | H19: 2 | I19: 4 | J19: 3 | K19: 4 | L19: 4 | M19: 1 | N19: 3 | V19: =SUM(B19:U19) -> 42 | W19: =V19/L4*20 -> 64.615385 | X19: =100-(AB48*2) -> 41.712472 | Y19: 8. Examen des besoins
A20: 9 | B20: 3 | C20: 4 | D20: 4 | E20: 4 | F20: 4 | G20: 4 | H20: 3 | I20: 4 | J20: 5 | K20: 4 | L20: 2 | M20: 2 | N20: 4 | V20: =SUM(B20:U20) -> 47 | W20: =V20/L4*20 -> 72.307692 | X20: =100-(AB49*2) -> 56.514075 | Y20: 9. Adaptation des activités
A21: 10 | B21: 5 | C21: 4 | D21: 4 | E21: 4 | F21: 4 | G21: 5 | H21: 3 | I21: 4 | J21: 5 | K21: 4 | L21: 2 | M21: 2 | N21: 4 | V21: =SUM(B21:U21) -> 50 | W21: =V21/L4*20 -> 76.923077 | X21: =100-(AB50*2) -> 50.645188 | Y21: 10. Leadership local
A22: 11 | B22: 5 | C22: 4 | D22: 4 | E22: 4 | F22: 4 | G22: 5 | H22: 3 | I22: 4 | J22: 1 | K22: 3 | L22: 2 | M22: 3 | N22: 4 | V22: =SUM(B22:U22) -> 46 | W22: =V22/L4*20 -> 70.769231 | X22: =100-(AB51*2) -> 43.669929 | Y22: 11. Capacités locales
A23: 12 | B23: 5 | C23: 4 | D23: 4 | E23: 4 | F23: 4 | G23: 4 | H23: 4 | I23: 4 | J23: 4 | K23: 4 | L23: 4 | M23: 3 | N23: 4 | V23: =SUM(B23:U23) -> 52 | W23: =V23/L4*20 -> 80 | X23: =100-(AB52*2) -> 79.587585 | Y23: 12. Implication des décideurs
A24: x | B24: =SUM(B12:B23) -> 52 | C24: =SUM(C12:C23) -> 42 | D24: =SUM(D12:D23) -> 41 | E24: =SUM(E12:E23) -> 48 | F24: =SUM(F12:F23) -> 48 | G24: =SUM(G12:G23) -> 46 | H24: =SUM(H12:H23) -> 31 | I24: =SUM(I12:I23) -> 50 | ... U24: =SUM(U12:U23) -> 0 | V24: =SUM(B24:U24) -> 529
A25: x2 | B25: =B24*B24 -> 2704 | C25: =C24*C24 -> 1764 | D25: =D24*D24 -> 1681 | E25: =E24*E24 -> 2304 | F25: =F24*F24 -> 2304 | G25: =G24*G24 -> 2116 | H25: =H24*H24 -> 961 | I25: =I24*I24 -> 2500 | ... U25: =U24*U24 -> 0 | V25: =SUM(B25:U25) -> 22357 | W25: z*
A39: Fiche de Calcul pour la note distincte capacit (x2)
A40: Element | B40: a | C40: b | D40: c | E40: d | F40: e | G40: f | H40: g | I40: h | J40: i | K40: j | L40: k | M40: l | N40: m | O40: n | P40: o | Q40: p | R40: q | S40: r | T40: s | U40: t | V40: Som x2 | W40: y* | X40: n* | Y40: m | Z40: p | AA40: sd | AB40: brute
A41: 1 | B41: =B12*B12 -> 25 | C41: =C12*C12 -> 16 | D41: =D12*D12 -> 16 | E41: =E12*E12 -> 16 | F41: =F12*F12 -> 16 | G41: =G12*G12 -> 16 | H41: =H12*H12 -> 16 | I41: =I12*I12 -> 16 | ... U41: =U12*U12 -> 0 | V41: =SUM(B41:U41) -> 207 | W41: =V12*V12 -> 2601 | X41: =L4*(L4-1) -> 156 | Y41: =L4*V41-W41 -> 90 | Z41: =Y41/X41 -> 0.57692308 | AA41: =SQRT(Z41) -> 0.75955453 | AB41: =AA41/4*100 -> 18.988863
A42: 2 | B42: =B13*B13 -> 16 | C42: =C13*C13 -> 16 | D42: =D13*D13 -> 16 | E42: =E13*E13 -> 25 | F42: =F13*F13 -> 25 | G42: =G13*G13 -> 16 | H42: =H13*H13 -> 16 | I42: =I13*I13 -> 25 | ... U42: =U13*U13 -> 0 | V42: =SUM(B42:U42) -> 228 | W42: =V13*V13 -> 2916 | X42: =L4*(L4-1) -> 156 | Y42: =L4*V42-W42 -> 48 | Z42: =Y42/X42 -> 0.30769231 | AA42: =SQRT(Z42) -> 0.5547002 | AB42: =AA42/4*100 -> 13.867505
A43: 3 | B43: =B14*B14 -> 16 | C43: =C14*C14 -> 16 | D43: =D14*D14 -> 9 | E43: =E14*E14 -> 4 | F43: =F14*F14 -> 16 | G43: =G14*G14 -> 9 | H43: =H14*H14 -> 4 | I43: =I14*I14 -> 16 | ... U43: =U14*U14 -> 0 | V43: =SUM(B43:U43) -> 115 | W43: =V14*V14 -> 1369 | X43: =L4*(L4-1) -> 156 | Y43: =L4*V43-W43 -> 126 | Z43: =Y43/X43 -> 0.80769231 | AA43: =SQRT(Z43) -> 0.89871703 | AB43: =AA43/4*100 -> 22.467926
A44: 4 | B44: =B15*B15 -> 25 | C44: =C15*C15 -> 4 | D44: =D15*D15 -> 4 | E44: =E15*E15 -> 16 | F44: =F15*F15 -> 16 | G44: =G15*G15 -> 16 | H44: =H15*H15 -> 1 | I44: =I15*I15 -> 16 | ... U44: =U15*U15 -> 0 | V44: =SUM(B44:U44) -> 117 | W44: =V15*V15 -> 1225 | X44: =L4*(L4-1) -> 156 | Y44: =L4*V44-W44 -> 296 | Z44: =Y44/X44 -> 1.8974359 | AA44: =SQRT(Z44) -> 1.3774745 | AB44: =AA44/4*100 -> 34.436862
A45: 5 | B45: =B16*B16 -> 9 | C45: =C16*C16 -> 4 | D45: =D16*D16 -> 4 | E45: =E16*E16 -> 16 | F45: =F16*F16 -> 16 | G45: =G16*G16 -> 9 | H45: =H16*H16 -> 1 | I45: =I16*I16 -> 16 | ... U45: =U16*U16 -> 0 | V45: =SUM(B45:U45) -> 99 | W45: =V16*V16 -> 1089 | X45: =L4*(L4-1) -> 156 | Y45: =L4*V45-W45 -> 198 | Z45: =Y45/X45 -> 1.2692308 | AA45: =SQRT(Z45) -> 1.1266014 | AB45: =AA45/4*100 -> 28.165036
A46: 6 | B46: =B17*B17 -> 25 | C46: =C17*C17 -> 16 | D46: =D17*D17 -> 16 | E46: =E17*E17 -> 16 | F46: =F17*F17 -> 9 | G46: =G17*G17 -> 9 | H46: =H17*H17 -> 4 | I46: =I17*I17 -> 16 | ... U46: =U17*U17 -> 0 | V46: =SUM(B46:U46) -> 143 | W46: =V17*V17 -> 1681 | X46: =L4*(L4-1) -> 156 | Y46: =L4*V46-W46 -> 178 | Z46: =Y46/X46 -> 1.1410256 | AA46: =SQRT(Z46) -> 1.068188 | AB46: =AA46/4*100 -> 26.7047
A47: 7 | B47: =B18*B18 -> 9 | C47: =C18*C18 -> 16 | D47: =D18*D18 -> 16 | E47: =E18*E18 -> 25 | F47: =F18*F18 -> 16 | G47: =G18*G18 -> 9 | H47: =H18*H18 -> 4 | I47: =I18*I18 -> 25 | ... U47: =U18*U18 -> 0 | V47: =SUM(B47:U47) -> 149 | W47: =V18*V18 -> 1681 | X47: =L4*(L4-1) -> 156 | Y47: =L4*V47-W47 -> 256 | Z47: =Y47/X47 -> 1.6410256 | AA47: =SQRT(Z47) -> 1.2810252 | AB47: =AA47/4*100 -> 32.025631
A48: 8 | B48: =B19*B19 -> 25 | C48: =C19*C19 -> 4 | D48: =D19*D19 -> 4 | E48: =E19*E19 -> 16 | F48: =F19*F19 -> 16 | G48: =G19*G19 -> 16 | H48: =H19*H19 -> 4 | I48: =I19*I19 -> 16 | ... U48: =U19*U19 -> 0 | V48: =SUM(B48:U48) -> 152 | W48: =V19*V19 -> 1764 | X48: =L4*(L4-1) -> 156 | Y48: =L4*V48-W48 -> 212 | Z48: =Y48/X48 -> 1.3589744 | AA48: =SQRT(Z48) -> 1.1657506 | AB48: =AA48/4*100 -> 29.143764
A49: 9 | B49: =B20*B20 -> 9 | C49: =C20*C20 -> 16 | D49: =D20*D20 -> 16 | E49: =E20*E20 -> 16 | F49: =F20*F20 -> 16 | G49: =G20*G20 -> 16 | H49: =H20*H20 -> 9 | I49: =I20*I20 -> 16 | ... U49: =U20*U20 -> 0 | V49: =SUM(B49:U49) -> 179 | W49: =V20*V20 -> 2209 | X49: =L4*(L4-1) -> 156 | Y49: =L4*V49-W49 -> 118 | Z49: =Y49/X49 -> 0.75641026 | AA49: =SQRT(Z49) -> 0.86971849 | AB49: =AA49/4*100 -> 21.742962
A50: 10 | B50: =B21*B21 -> 25 | C50: =C21*C21 -> 16 | D50: =D21*D21 -> 16 | E50: =E21*E21 -> 16 | F50: =F21*F21 -> 16 | G50: =G21*G21 -> 25 | H50: =H21*H21 -> 9 | I50: =I21*I21 -> 16 | ... U50: =U21*U21 -> 0 | V50: =SUM(B50:U50) -> 204 | W50: =V21*V21 -> 2500 | X50: =L4*(L4-1) -> 156 | Y50: =L4*V50-W50 -> 152 | Z50: =Y50/X50 -> 0.97435897 | AA50: =SQRT(Z50) -> 0.98709623 | AB50: =AA50/4*100 -> 24.677406
A51: 11 | B51: =B22*B22 -> 25 | C51: =C22*C22 -> 16 | D51: =D22*D22 -> 16 | E51: =E22*E22 -> 16 | F51: =F22*F22 -> 16 | G51: =G22*G22 -> 25 | H51: =H22*H22 -> 9 | I51: =I22*I22 -> 16 | ... U51: =U22*U22 -> 0 | V51: =SUM(B51:U51) -> 178 | W51: =V22*V22 -> 2116 | X51: =L4*(L4-1) -> 156 | Y51: =L4*V51-W51 -> 198 | Z51: =Y51/X51 -> 1.2692308 | AA51: =SQRT(Z51) -> 1.1266014 | AB51: =AA51/4*100 -> 28.165036
A52: 12 | B52: =B23*B23 -> 25 | C52: =C23*C23 -> 16 | D52: =D23*D23 -> 16 | E52: =E23*E23 -> 16 | F52: =F23*F23 -> 16 | G52: =G23*G23 -> 16 | H52: =H23*H23 -> 16 | I52: =I23*I23 -> 16 | ... U52: =U23*U23 -> 0 | V52: =SUM(B52:U52) -> 210 | W52: =V23*V23 -> 2704 | X52: =L4*(L4-1) -> 156 | Y52: =L4*V52-W52 -> 26 | Z52: =Y52/X52 -> 0.16666667 | AA52: =SQRT(Z52) -> 0.40824829 | AB52: =AA52/4*100 -> 10.206207

Sheet Dur
A1: Durabilite (Perennisation) des Acquis du Programme
L2: (Calculs) | W2: Interpretation de la Note Standardisee:
B3: Standardisee | L3: Nbre de Sondes | P3: =V24*V24 -> 284089 | Q3: y* | W3: 20-39 | X3: Loin en dessous de la moyenne / niveau acceptable
A4: =(P8/L6)*100 -> 68.333333 | B4: Note Capacite | L4: 13 | P4: =L4*(L4-1) -> 156 | Q4: n* | W4: 40-59 | X4: Au dessus de la moyenne / niveau acceptable
A5: =100-(P9*2) -> 61.887715 | B5: Note Consensus | L5: Points Max | P5: =(L4*V25)-P3 -> 13052 | Q5: m | W5: 60-70 | X5: Moyen / niveau acceptable
L6: =A23*5 -> 60 | P6: =P5/P4 -> 83.666667 | Q6: p | W6: 71-80 | X6: Au dessus de la moyenne / niveau acceptable
L7: Nbre de Questions | P7: =SQRT(P6) -> 9.1469485 | Q7: SD | W7: 81-100 | X7: Loin au-dessus de la moyenne / niveau acceptable
L8: 12 | P8: =V24/L4 -> 41 | Q8: Note Brute Cap
P9: =P7/((L8*5)-(L8*1))*100 -> 19.056143 | Q9: Note Brute Cons
B10: Respondents | F10: 5 | K10: 10 | P10: 15 | U10: 20 | W10: Notes Standardisees Par Element
A11: Element | B11: a | C11: b | D11: c | E11: d | F11: e | G11: f | H11: g | I11: h | J11: i | K11: j | L11: k | M11: l | N11: m | O11: n | P11: o | Q11: p | R11: q | S11: r | T11: s | U11: t | V11: Somme | W11: Note Cap | X11: Note Cons | Y11: Elements
A12: 1 | B12: 4 | C12: 4 | D12: 5 | E12: 4 | F12: 4 | G12: 4 | H12: 5 | I12: 4 | J12: 4 | K12: 1 | L12: 3 | M12: 4 | N12: 4 | V12: =SUM(B12:U12) -> 50 | W12: =V12/L4*20 -> 76.923077 | X12: =100-(AB36*2) -> 50.645188 | Y12: 1. D. économique pour conception
A13: 2 | B13: 3 | C13: 5 | D13: 1 | E13: 3 | F13: 4 | G13: 3 | H13: 4 | I13: 5 | J13: 4 | K13: 1 | L13: 1 | M13: 2 | N13: 2 | V13: =SUM(B13:U13) -> 38 | W13: =V13/L4*20 -> 58.461538 | X13: =100-(AB37*2) -> 27.942331 | Y13: 2. D. politique pour conception
A14: 3 | B14: 4 | C14: 4 | D14: 3 | E14: 4 | F14: 4 | G14: 4 | H14: 2 | I14: 4 | J14: 4 | K14: 4 | L14: 1 | M14: 2 | N14: 4 | V14: =SUM(B14:U14) -> 44 | W14: =V14/L4*20 -> 67.692308 | X14: =100-(AB38*2) -> 47.804608 | Y14: 3. D. institutionnelle pour conception
A15: 4 | B15: 4 | C15: 3 | D15: 1 | E15: 4 | F15: 4 | G15: 4 | H15: 4 | I15: 5 | J15: 3 | K15: 4 | L15: 1 | M15: 2 | N15: 2 | V15: =SUM(B15:U15) -> 41 | W15: =V15/L4*20 -> 63.076923 | X15: =100-(AB39*2) -> 35.948738 | Y15: 4. D. sociale pour conception
A16: 5 | B16: 4 | C16: 5 | D16: 3 | E16: 3 | F16: 4 | G16: 4 | H16: 5 | I16: 5 | J16: 3 | K16: 2 | L16: 1 | M16: 2 | N16: 2 | V16: =SUM(B16:U16) -> 43 | W16: =V16/L4*20 -> 66.153846 | X16: =100-(AB40*2) -> 34.220649 | Y16: 5. D. environnementale pour exécution
A17: 6 | B17: 4 | C17: 4 | D17: 4 | E17: 3 | F17: 4 | G17: 5 | H17: 4 | I17: 5 | J17: 3 | K17: 4 | L17: 3 | M17: 2 | N17: 2 | V17: =SUM(B17:U17) -> 47 | W17: =V17/L4*20 -> 72.307692 | X17: =100-(AB41*2) -> 51.961554 | Y17: 6. D. économique exécution
A18: 7 | B18: 4 | C18: 4 | D18: 4 | E18: 4 | F18: 4 | G18: 4 | H18: 4 | I18: 5 | J18: 3 | K18: 4 | L18: 4 | M18: 3 | N18: 4 | V18: =SUM(B18:U18) -> 51 | W18: =V18/L4*20 -> 78.461538 | X18: =100-(AB42*2) -> 75.322594 | Y18: 7. D. institutionnelle pour exécution
A19: 8 | B19: 4 | C19: 4 | D19: 4 | E19: 4 | F19: 4 | G19: 5 | H19: 4 | I19: 5 | J19: 3 | K19: 3 | L19: 1 | M19: 2 | N19: 2 | V19: =SUM(B19:U19) -> 45 | W19: =V19/L4*20 -> 69.230769 | X19: =100-(AB43*2) -> 40.085531 | Y19: 8. D. sociale pour exécution
A20: 9 | B20: 4 | C20: 4 | D20: 3 | E20: 3 | F20: 3 | G20: 4 | H20: 5 | I20: 4 | J20: 3 | K20: 2 | L20: 1 | M20: 2 | N20: 2 | V20: =SUM(B20:U20) -> 40 | W20: =V20/L4*20 -> 61.538462 | X20: =100-(AB44*2) -> 44.241822 | Y20: 9. D. environnementale pour S&E
A21: 10 | B21: 4 | C21: 4 | D21: 3 | E21: 4 | F21: 4 | G21: 4 | H21: 4 | I21: 5 | J21: 2 | K21: 4 | L21: 5 | M21: 2 | N21: 4 | V21: =SUM(B21:U21) -> 49 | W21: =V21/L4*20 -> 75.384615 | X21: =100-(AB45*2) -> 53.659565 | Y21: 10. D. économique pour S&E
A22: 11 | B22: 4 | C22: 4 | D22: 3 | E22: 3 | F22: 2 | G22: 4 | H22: 3 | I22: 5 | J22: 2 | K22: 2 | L22: 4 | M22: 2 | N22: 4 | V22: =SUM(B22:U22) -> 42 | W22: =V22/L4*20 -> 64.615385 | X22: =100-(AB46*2) -> 49.363032 | Y22: 11. D. institutionnelle pour S&E
A23: 12 | B23: 5 | C23: 4 | D23: 4 | E23: 5 | F23: 2 | G23: 4 | H23: 3 | I23: 4 | J23: 4 | K23: 4 | L23: 1 | M23: 1 | N23: 2 | V23: =SUM(B23:U23) -> 43 | W23: =V23/L4*20 -> 66.153846 | X23: =100-(AB47*2) -> 31.126277 | Y23: 12. Appui technique
A24: x | B24: =SUM(B12:B23) -> 48 | C24: =SUM(C12:C23) -> 49 | D24: =SUM(D12:D23) -> 38 | E24: =SUM(E12:E23) -> 44 | F24: =SUM(F12:F23) -> 43 | G24: =SUM(G12:G23) -> 49 | H24: =SUM(H12:H23) -> 47 | I24: =SUM(I12:I23) -> 56 | ... U24: =SUM(U12:U23) -> 0 | V24: =SUM(B24:U24) -> 533
A25: x2 | B25: =B24*B24 -> 2304 | C25: =C24*C24 -> 2401 | D25: =D24*D24 -> 1444 | E25: =E24*E24 -> 1936 | F25: =F24*F24 -> 1849 | G25: =G24*G24 -> 2401 | H25: =H24*H24 -> 2209 | I25: =I24*I24 -> 3136 | ... U25: =U24*U24 -> 0 | V25: =SUM(B25:U25) -> 22857 | W25: z*
A34: Feuille de Calcul pour la note distincte capacite (x2)
A35: Element | B35: a | C35: b | D35: c | E35: d | F35: e | G35: f | H35: g | I35: h | J35: i | K35: j | L35: k | M35: l | N35: m | O35: n | P35: o | Q35: p | R35: q | S35: r | T35: s | U35: t | V35: Som x2 | W35: y* | X35: n* | Y35: m | Z35: p | AA35: sd | AB35: brute
A36: 1 | B36: =B12*B12 -> 16 | C36: =C12*C12 -> 16 | D36: =D12*D12 -> 25 | E36: =E12*E12 -> 16 | F36: =F12*F12 -> 16 | G36: =G12*G12 -> 16 | H36: =H12*H12 -> 25 | I36: =I12*I12 -> 16 | ... U36: =U12*U12 -> 0 | V36: =SUM(B36:U36) -> 204 | W36: =V12*V12 -> 2500 | X36: =L4*(L4-1) -> 156 | Y36: =L4*V36-W36 -> 152 | Z36: =Y36/X36 -> 0.97435897 | AA36: =SQRT(Z36) -> 0.98709623 | AB36: =AA36/4*100 -> 24.677406
A37: 2 | B37: =B13*B13 -> 9 | C37: =C13*C13 -> 25 | D37: =D13*D13 -> 1 | E37: =E13*E13 -> 9 | F37: =F13*F13 -> 16 | G37: =G13*G13 -> 9 | H37: =H13*H13 -> 16 | I37: =I13*I13 -> 25 | ... U37: =U13*U13 -> 0 | V37: =SUM(B37:U37) -> 136 | W37: =V13*V13 -> 1444 | X37: =L4*(L4-1) -> 156 | Y37: =L4*V37-W37 -> 324 | Z37: =Y37/X37 -> 2.0769231 | AA37: =SQRT(Z37) -> 1.4411534 | AB37: =AA37/4*100 -> 36.028835
A38: 3 | B38: =B14*B14 -> 16 | C38: =C14*C14 -> 16 | D38: =D14*D14 -> 9 | E38: =E14*E14 -> 16 | F38: =F14*F14 -> 16 | G38: =G14*G14 -> 16 | H38: =H14*H14 -> 4 | I38: =I14*I14 -> 16 | ... U38: =U14*U14 -> 0 | V38: =SUM(B38:U38) -> 162 | W38: =V14*V14 -> 1936 | X38: =L4*(L4-1) -> 156 | Y38: =L4*V38-W38 -> 170 | Z38: =Y38/X38 -> 1.0897436 | AA38: =SQRT(Z38) -> 1.0439078 | AB38: =AA38/4*100 -> 26.097696
A39: 4 | B39: =B15*B15 -> 16 | C39: =C15*C15 -> 9 | D39: =D15*D15 -> 1 | E39: =E15*E15 -> 16 | F39: =F15*F15 -> 16 | G39: =G15*G15 -> 16 | H39: =H15*H15 -> 16 | I39: =I15*I15 -> 25 | ... U39: =U15*U15 -> 0 | V39: =SUM(B39:U39) -> 149 | W39: =V15*V15 -> 1681 | X39: =L4*(L4-1) -> 156 | Y39: =L4*V39-W39 -> 256 | Z39: =Y39/X39 -> 1.6410256 | AA39: =SQRT(Z39) -> 1.2810252 | AB39: =AA39/4*100 -> 32.025631
A40: 5 | B40: =B16*B16 -> 16 | C40: =C16*C16 -> 25 | D40: =D16*D16 -> 9 | E40: =E16*E16 -> 9 | F40: =F16*F16 -> 16 | G40: =G16*G16 -> 16 | H40: =H16*H16 -> 25 | I40: =I16*I16 -> 25 | ... U40: =U16*U16 -> 0 | V40: =SUM(B40:U40) -> 163 | W40: =V16*V16 -> 1849 | X40: =L4*(L4-1) -> 156 | Y40: =L4*V40-W40 -> 270 | Z40: =Y40/X40 -> 1.7307692 | AA40: =SQRT(Z40) -> 1.315587 | AB40: =AA40/4*100 -> 32.889676
A41: 6 | B41: =B17*B17 -> 16 | C41: =C17*C17 -> 16 | D41: =D17*D17 -> 16 | E41: =E17*E17 -> 9 | F41: =F17*F17 -> 16 | G41: =G17*G17 -> 25 | H41: =H17*H17 -> 16 | I41: =I17*I17 -> 25 | ... U41: =U17*U17 -> 0 | V41: =SUM(B41:U41) -> 181 | W41: =V17*V17 -> 2209 | X41: =L4*(L4-1) -> 156 | Y41: =L4*V41-W41 -> 144 | Z41: =Y41/X41 -> 0.92307692 | AA41: =SQRT(Z41) -> 0.96076892 | AB41: =AA41/4*100 -> 24.019223
A42: 7 | B42: =B18*B18 -> 16 | C42: =C18*C18 -> 16 | D42: =D18*D18 -> 16 | E42: =E18*E18 -> 16 | F42: =F18*F18 -> 16 | G42: =G18*G18 -> 16 | H42: =H18*H18 -> 16 | I42: =I18*I18 -> 25 | ... U42: =U18*U18 -> 0 | V42: =SUM(B42:U42) -> 203 | W42: =V18*V18 -> 2601 | X42: =L4*(L4-1) -> 156 | Y42: =L4*V42-W42 -> 38 | Z42: =Y42/X42 -> 0.24358974 | AA42: =SQRT(Z42) -> 0.49354812 | AB42: =AA42/4*100 -> 12.338703
A43: 8 | B43: =B19*B19 -> 16 | C43: =C19*C19 -> 16 | D43: =D19*D19 -> 16 | E43: =E19*E19 -> 16 | F43: =F19*F19 -> 16 | G43: =G19*G19 -> 25 | H43: =H19*H19 -> 16 | I43: =I19*I19 -> 25 | ... U43: =U19*U19 -> 0 | V43: =SUM(B43:U43) -> 173 | W43: =V19*V19 -> 2025 | X43: =L4*(L4-1) -> 156 | Y43: =L4*V43-W43 -> 224 | Z43: =Y43/X43 -> 1.4358974 | AA43: =SQRT(Z43) -> 1.1982894 | AB43: =AA43/4*100 -> 29.957234
A44: 9 | B44: =B20*B20 -> 16 | C44: =C20*C20 -> 16 | D44: =D20*D20 -> 9 | E44: =E20*E20 -> 9 | F44: =F20*F20 -> 9 | G44: =G20*G20 -> 16 | H44: =H20*H20 -> 25 | I44: =I20*I20 -> 16 | ... U44: =U20*U20 -> 0 | V44: =SUM(B44:U44) -> 138 | W44: =V20*V20 -> 1600 | X44: =L4*(L4-1) -> 156 | Y44: =L4*V44-W44 -> 194 | Z44: =Y44/X44 -> 1.2435897 | AA44: =SQRT(Z44) -> 1.1151636 | AB44: =AA44/4*100 -> 27.879089
A45: 10 | B45: =B21*B21 -> 16 | C45: =C21*C21 -> 16 | D45: =D21*D21 -> 9 | E45: =E21*E21 -> 16 | F45: =F21*F21 -> 16 | G45: =G21*G21 -> 16 | H45: =H21*H21 -> 16 | I45: =I21*I21 -> 25 | ... U45: =U21*U21 -> 0 | V45: =SUM(B45:U45) -> 195 | W45: =V21*V21 -> 2401 | X45: =L4*(L4-1) -> 156 | Y45: =L4*V45-W45 -> 134 | Z45: =Y45/X45 -> 0.85897436 | AA45: =SQRT(Z45) -> 0.9268087 | AB45: =AA45/4*100 -> 23.170217
A46: 11 | B46: =B22*B22 -> 16 | C46: =C22*C22 -> 16 | D46: =D22*D22 -> 9 | E46: =E22*E22 -> 9 | F46: =F22*F22 -> 4 | G46: =G22*G22 -> 16 | H46: =H22*H22 -> 9 | I46: =I22*I22 -> 25 | ... U46: =U22*U22 -> 0 | V46: =SUM(B46:U46) -> 148 | W46: =V22*V22 -> 1764 | X46: =L4*(L4-1) -> 156 | Y46: =L4*V46-W46 -> 160 | Z46: =Y46/X46 -> 1.025641 | AA46: =SQRT(Z46) -> 1.0127394 | AB46: =AA46/4*100 -> 25.318484
A47: 12 | B47: =B23*B23 -> 25 | C47: =C23*C23 -> 16 | D47: =D23*D23 -> 16 | E47: =E23*E23 -> 25 | F47: =F23*F23 -> 4 | G47: =G23*G23 -> 16 | H47: =H23*H23 -> 9 | I47: =I23*I23 -> 16 | ... U47: =U23*U23 -> 0 | V47: =SUM(B47:U47) -> 165 | W47: =V23*V23 -> 1849 | X47: =L4*(L4-1) -> 156 | Y47: =L4*V47-W47 -> 296 | Z47: =Y47/X47 -> 1.8974359 | AA47: =SQRT(Z47) -> 1.3774745 | AB47: =AA47/4*100 -> 34.436862

Sheet Partn
A1: Partenariat
L2: (Calculs) | W2: Interpretation de la Note Standardisee:
B3: Standardisee | L3: Nbre de Sondes | P3: =V25*V25 -> 240100 | Q3: y* | W3: 20-39 | X3: Loin en dessous de la moyenne / niveau acceptable
A4: =(P8/L6)*100 -> 68.531469 | B4: Note Capacite | L4: 11 | P4: =L4*(L4-1) -> 110 | Q4: n* | W4: 40-59 | X4: Au dessus de la moyenne / niveau acceptable
A5: =100-(P9*2) -> 74.934191 | B5: Note Consensus | L5: Points Max | P5: =(L4*V26)-P3 -> 4672 | Q5: m | W5: 60-70 | X5: Moyen / niveau acceptable
L6: =A24*5 -> 65 | P6: =P5/P4 -> 42.472727 | Q6: p | W6: 71-80 | X6: Au dessus de la moyenne / niveau acceptable
L7: Nbre de Questions | P7: =SQRT(P6) -> 6.5171103 | Q7: SD | W7: 81-100 | X7: Loin au-dessus de la moyenne / niveau acceptable
L8: 13 | P8: =V25/L4 -> 44.545455 | Q8: Note brute Cap
P9: =P7/((L8*5)-(L8*1))*100 -> 12.532905 | Q9: Note Brute Cons
B10: Sondes | F10: 5 | K10: 10 | P10: 15 | U10: 20 | W10: Notes Standardises Par Element
A11: Elements | B11: a | C11: b | D11: c | E11: d | F11: e | G11: f | H11: g | I11: h | J11: i | K11: j | L11: k | M11: l | N11: m | O11: n | P11: o | Q11: p | R11: q | S11: r | T11: s | U11: t | V11: Somme | W11: Note Cap | X11: Note Cons | Y11: Elements
A12: 1 | B12: 2 | C12: 2 | D12: 4 | E12: 4 | F12: 4 | G12: 5 | H12: 4 | I12: 4 | J12: 3 | K12: 2 | L12: 4 | V12: =SUM(B12:U12) -> 38 | W12: =V12/L4*20 -> 69.090909 | X12: =100-(AB43*2) -> 48.213726 | Y12: 1. Liens avec les politiques
A13: 2 | B13: 2 | C13: 2 | D13: 4 | E13: 3 | F13: 3 | G13: 3 | H13: 3 | I13: 2 | J13: 3 | K13: 2 | L13: 4 | V13: =SUM(B13:U13) -> 31 | W13: =V13/L4*20 -> 56.363636 | X13: =100-(AB44*2) -> 62.46214 | Y13: 2. Liens avec Secteur privé
A14: 3 | B14: 2 | C14: 4 | D14: 4 | E14: 3 | F14: 2 | G14: 5 | H14: 4 | I14: 2 | J14: 3 | K14: 4 | L14: 4 | V14: =SUM(B14:U14) -> 37 | W14: =V14/L4*20 -> 67.272727 | X14: =100-(AB45*2) -> 48.654468 | Y14: 3. Liens avec ONG
A15: 4 | B15: 2 | C15: 2 | D15: 3 | E15: 3 | F15: 2 | G15: 5 | H15: 5 | I15: 2 | J15: 3 | K15: 4 | L15: 4 | V15: =SUM(B15:U15) -> 35 | W15: =V15/L4*20 -> 63.636364 | X15: =100-(AB46*2) -> 41.612579 | Y15: 4. Liens avec autres CL
A16: 5 | B16: 4 | C16: 4 | D16: 3 | E16: 3 | F16: 2 | G16: 3 | H16: 5 | I16: 3 | J16: 2 | K16: 3 | L16: 4 | V16: =SUM(B16:U16) -> 36 | W16: =V16/L4*20 -> 65.454545 | X16: =100-(AB47*2) -> 54.773298 | Y16: 5. Partenariats avec Organisations
A17: 6 | B17: 2 | C17: 2 | D17: 3 | E17: 2 | F17: 2 | G17: 3 | H17: 4 | I17: 2 | J17: 3 | K17: 3 | L17: 4 | V17: =SUM(B17:U17) -> 30 | W17: =V17/L4*20 -> 54.545455 | X17: =100-(AB48*2) -> 60.68773 | Y17: 6. Suivi de l’efficacité
A18: 7 | B18: 2 | C18: 2 | D18: 4 | E18: 4 | F18: 4 | G18: 5 | H18: 4 | I18: 4 | J18: 4 | K18: 4 | L18: 4 | V18: =SUM(B18:U18) -> 41 | W18: =V18/L4*20 -> 74.545455 | X18: =100-(AB49*2) -> 54.773298 | Y18: 7. Avantages financiers
A19: 8 | B19: 4 | C19: 2 | D19: 4 | E19: 4 | F19: 4 | G19: 5 | H19: 4 | I19: 4 | J19: 4 | K19: 4 | L19: 4 | V19: =SUM(B19:U19) -> 43 | W19: =V19/L4*20 -> 78.181818 | X19: =100-(AB50*2) -> 64.967548 | Y19: 8. Compétences techniques
A20: 9 | B20: 4 | C20: 4 | D20: 4 | E20: 4 | F20: 4 | G20: 5 | H20: 5 | I20: 4 | J20: 4 | K20: 4 | L20: 4 | V20: =SUM(B20:U20) -> 46 | W20: =V20/L4*20 -> 83.636364 | X20: =100-(AB51*2) -> 79.774004 | Y20: 9. Relations et réseaux nouveaux
A21: 10 | B21: 2 | C21: 3 | D21: 2 | E21: 3 | F21: 4 | G21: 5 | H21: 3 | I21: 3 | J21: 3 | K21: 3 | L21: 4 | V21: =SUM(B21:U21) -> 35 | W21: =V21/L4*20 -> 63.636364 | X21: =100-(AB52*2) -> 56.306855 | Y21: 10. Informations partagées
A22: 11 | B22: 4 | C22: 2 | D22: 2 | E22: 4 | F22: 4 | G22: 5 | H22: 4 | I22: 4 | J22: 4 | K22: 4 | L22: 4 | V22: =SUM(B22:U22) -> 41 | W22: =V22/L4*20 -> 74.545455 | X22: =100-(AB53*2) -> 54.773298 | Y22: 11. Confiance et coopération
A23: 12 | B23: 4 | C23: 4 | D23: 2 | E23: 3 | F23: 4 | G23: 4 | H23: 4 | I23: 2 | J23: 3 | K23: 4 | L23: 4 | V23: =SUM(B23:U23) -> 38 | W23: =V23/L4*20 -> 69.090909 | X23: =100-(AB54*2) -> 58.990023 | Y23: 12. Objectifs partagés
A24: 13 | B24: 4 | C24: 4 | D24: 4 | E24: 4 | F24: 3 | G24: 4 | H24: 3 | I24: 2 | J24: 3 | K24: 4 | L24: 4 | V24: =SUM(B24:U24) -> 39 | W24: =V24/L4*20 -> 70.909091 | X24: =100-(AB55*2) -> 65.622417 | Y24: 13. Participation à la coopération
A25: x | B25: =SUM(B12:B24) -> 38 | C25: =SUM(C12:C24) -> 37 | D25: =SUM(D12:D24) -> 43 | E25: =SUM(E12:E24) -> 44 | F25: =SUM(F12:F24) -> 42 | G25: =SUM(G12:G24) -> 57 | H25: =SUM(H12:H24) -> 52 | I25: =SUM(I12:I24) -> 38 | ... U25: =SUM(U12:U24) -> 0 | V25: =SUM(B25:U25) -> 490
A26: x2 | B26: =B25*B25 -> 1444 | C26: =C25*C25 -> 1369 | D26: =D25*D25 -> 1849 | E26: =E25*E25 -> 1936 | F26: =F25*F25 -> 1764 | G26: =G25*G25 -> 3249 | H26: =H25*H25 -> 2704 | I26: =I25*I25 -> 1444 | ... U26: =U25*U25 -> 0 | V26: =SUM(B26:U26) -> 22252
A41: Fiche de Calcul pour la note distincte capacite (x2)
A42: Element | B42: a | C42: b | D42: c | E42: d | F42: e | G42: f | H42: g | I42: h | J42: i | K42: j | L42: k | M42: l | N42: m | O42: n | P42: o | Q42: p | R42: q | S42: r | T42: s | U42: t | V42: Som x2 | W42: y* | X42: n* | Y42: m | Z42: p | AA42: sd | AB42: brute
A43: 1 | B43: =B12*B12 -> 4 | C43: =C12*C12 -> 4 | D43: =D12*D12 -> 16 | E43: =E12*E12 -> 16 | F43: =F12*F12 -> 16 | G43: =G12*G12 -> 25 | H43: =H12*H12 -> 16 | I43: =I12*I12 -> 16 | ... U43: =U12*U12 -> 0 | V43: =SUM(B43:U43) -> 142 | W43: =V12*V12 -> 1444 | X43: =L4*(L4-1) -> 110 | Y43: =L4*V43-W43 -> 118 | Z43: =Y43/X43 -> 1.0727273 | AA43: =SQRT(Z43) -> 1.0357255 | AB43: =AA43/4*100 -> 25.893137
A44: 2 | B44: =B13*B13 -> 4 | C44: =C13*C13 -> 4 | D44: =D13*D13 -> 16 | E44: =E13*E13 -> 9 | F44: =F13*F13 -> 9 | G44: =G13*G13 -> 9 | H44: =H13*H13 -> 9 | I44: =I13*I13 -> 4 | ... U44: =U13*U13 -> 0 | V44: =SUM(B44:U44) -> 93 | W44: =V13*V13 -> 961 | X44: =L4*(L4-1) -> 110 | Y44: =L4*V44-W44 -> 62 | Z44: =Y44/X44 -> 0.56363636 | AA44: =SQRT(Z44) -> 0.75075719 | AB44: =AA44/4*100 -> 18.76893
A45: 3 | B45: =B14*B14 -> 4 | C45: =C14*C14 -> 16 | D45: =D14*D14 -> 16 | E45: =E14*E14 -> 9 | F45: =F14*F14 -> 4 | G45: =G14*G14 -> 25 | H45: =H14*H14 -> 16 | I45: =I14*I14 -> 4 | ... U45: =U14*U14 -> 0 | V45: =SUM(B45:U45) -> 135 | W45: =V14*V14 -> 1369 | X45: =L4*(L4-1) -> 110 | Y45: =L4*V45-W45 -> 116 | Z45: =Y45/X45 -> 1.0545455 | AA45: =SQRT(Z45) -> 1.0269106 | AB45: =AA45/4*100 -> 25.672766
A46: 4 | B46: =B15*B15 -> 4 | C46: =C15*C15 -> 4 | D46: =D15*D15 -> 9 | E46: =E15*E15 -> 9 | F46: =F15*F15 -> 4 | G46: =G15*G15 -> 25 | H46: =H15*H15 -> 25 | I46: =I15*I15 -> 4 | ... U46: =U15*U15 -> 0 | V46: =SUM(B46:U46) -> 125 | W46: =V15*V15 -> 1225 | X46: =L4*(L4-1) -> 110 | Y46: =L4*V46-W46 -> 150 | Z46: =Y46/X46 -> 1.3636364 | AA46: =SQRT(Z46) -> 1.1677484 | AB46: =AA46/4*100 -> 29.19371
A47: 5 | B47: =B16*B16 -> 16 | C47: =C16*C16 -> 16 | D47: =D16*D16 -> 9 | E47: =E16*E16 -> 9 | F47: =F16*F16 -> 4 | G47: =G16*G16 -> 9 | H47: =H16*H16 -> 25 | I47: =I16*I16 -> 9 | ... U47: =U16*U16 -> 0 | V47: =SUM(B47:U47) -> 126 | W47: =V16*V16 -> 1296 | X47: =L4*(L4-1) -> 110 | Y47: =L4*V47-W47 -> 90 | Z47: =Y47/X47 -> 0.81818182 | AA47: =SQRT(Z47) -> 0.90453403 | AB47: =AA47/4*100 -> 22.613351
A48: 6 | B48: =B17*B17 -> 4 | C48: =C17*C17 -> 4 | D48: =D17*D17 -> 9 | E48: =E17*E17 -> 4 | F48: =F17*F17 -> 4 | G48: =G17*G17 -> 9 | H48: =H17*H17 -> 16 | I48: =I17*I17 -> 4 | ... U48: =U17*U17 -> 0 | V48: =SUM(B48:U48) -> 88 | W48: =V17*V17 -> 900 | X48: =L4*(L4-1) -> 110 | Y48: =L4*V48-W48 -> 68 | Z48: =Y48/X48 -> 0.61818182 | AA48: =SQRT(Z48) -> 0.78624539 | AB48: =AA48/4*100 -> 19.656135
A49: 7 | B49: =B18*B18 -> 4 | C49: =C18*C18 -> 4 | D49: =D18*D18 -> 16 | E49: =E18*E18 -> 16 | F49: =F18*F18 -> 16 | G49: =G18*G18 -> 25 | H49: =H18*H18 -> 16 | I49: =I18*I18 -> 16 | ... U49: =U18*U18 -> 0 | V49: =SUM(B49:U49) -> 161 | W49: =V18*V18 -> 1681 | X49: =L4*(L4-1) -> 110 | Y49: =L4*V49-W49 -> 90 | Z49: =Y49/X49 -> 0.81818182 | AA49: =SQRT(Z49) -> 0.90453403 | AB49: =AA49/4*100 -> 22.613351
A50: 8 | B50: =B19*B19 -> 16 | C50: =C19*C19 -> 4 | D50: =D19*D19 -> 16 | E50: =E19*E19 -> 16 | F50: =F19*F19 -> 16 | G50: =G19*G19 -> 25 | H50: =H19*H19 -> 16 | I50: =I19*I19 -> 16 | ... U50: =U19*U19 -> 0 | V50: =SUM(B50:U50) -> 173 | W50: =V19*V19 -> 1849 | X50: =L4*(L4-1) -> 110 | Y50: =L4*V50-W50 -> 54 | Z50: =Y50/X50 -> 0.49090909 | AA50: =SQRT(Z50) -> 0.70064905 | AB50: =AA50/4*100 -> 17.516226
A51: 9 | B51: =B20*B20 -> 16 | C51: =C20*C20 -> 16 | D51: =D20*D20 -> 16 | E51: =E20*E20 -> 16 | F51: =F20*F20 -> 16 | G51: =G20*G20 -> 25 | H51: =H20*H20 -> 25 | I51: =I20*I20 -> 16 | ... U51: =U20*U20 -> 0 | V51: =SUM(B51:U51) -> 194 | W51: =V20*V20 -> 2116 | X51: =L4*(L4-1) -> 110 | Y51: =L4*V51-W51 -> 18 | Z51: =Y51/X51 -> 0.16363636 | AA51: =SQRT(Z51) -> 0.40451992 | AB51: =AA51/4*100 -> 10.112998
A52: 10 | B52: =B21*B21 -> 4 | C52: =C21*C21 -> 9 | D52: =D21*D21 -> 4 | E52: =E21*E21 -> 9 | F52: =F21*F21 -> 16 | G52: =G21*G21 -> 25 | H52: =H21*H21 -> 9 | I52: =I21*I21 -> 9 | ... U52: =U21*U21 -> 0 | V52: =SUM(B52:U52) -> 119 | W52: =V21*V21 -> 1225 | X52: =L4*(L4-1) -> 110 | Y52: =L4*V52-W52 -> 84 | Z52: =Y52/X52 -> 0.76363636 | AA52: =SQRT(Z52) -> 0.8738629 | AB52: =AA52/4*100 -> 21.846572
A53: 11 | B53: =B22*B22 -> 16 | C53: =C22*C22 -> 4 | D53: =D22*D22 -> 4 | E53: =E22*E22 -> 16 | F53: =F22*F22 -> 16 | G53: =G22*G22 -> 25 | H53: =H22*H22 -> 16 | I53: =I22*I22 -> 16 | ... U53: =U22*U22 -> 0 | V53: =SUM(B53:U53) -> 161 | W53: =V22*V22 -> 1681 | X53: =L4*(L4-1) -> 110 | Y53: =L4*V53-W53 -> 90 | Z53: =Y53/X53 -> 0.81818182 | AA53: =SQRT(Z53) -> 0.90453403 | AB53: =AA53/4*100 -> 22.613351
A54: 12 | B54: =B23*B23 -> 16 | C54: =C23*C23 -> 16 | D54: =D23*D23 -> 4 | E54: =E23*E23 -> 9 | F54: =F23*F23 -> 16 | G54: =G23*G23 -> 16 | H54: =H23*H23 -> 16 | I54: =I23*I23 -> 4 | ... U54: =U23*U23 -> 0 | V54: =SUM(B54:U54) -> 138 | W54: =V23*V23 -> 1444 | X54: =L4*(L4-1) -> 110 | Y54: =L4*V54-W54 -> 74 | Z54: =Y54/X54 -> 0.67272727 | AA54: =SQRT(Z54) -> 0.82019953 | AB54: =AA54/4*100 -> 20.504988
...

Sheet Gouv
A1: Gouvernance et Gestion Strategique
L2: (Calculs) | W2: Interpretation de la Note Standardisee:
B3: Standardisee | L3: Nbre de Sondes | P3: =V27*V27 -> 535824 | Q3: y* | W3: 20-39 | X3: Loin en dessous de la moyenne / niveau acceptable
A4: =(P8/L6)*100 -> 75.076923 | B4: Note Capacite | L4: 13 | P4: =L4*(L4-1) -> 156 | Q4: n* | W4: 40-59 | X4: Au dessus de la moyenne / niveau acceptable
A5: =100-(P9*2) -> 76.141442 | B5: Note Consensus | L5: Points Max | P5: =(L4*V28)-P3 -> 7992 | Q5: m | W5: 60-70 | X5: Moyen / niveau acceptable
L6: =A26*5 -> 75 | P6: =P5/P4 -> 51.230769 | Q6: p | W6: 71-80 | X6: Au dessus de la moyenne / niveau acceptable
L7: Nbre de Questions | P7: =SQRT(P6) -> 7.1575673 | Q7: SD | W7: 81-100 | X7: Loin au-dessus de la moyenne / niveau acceptable
L8: 15 | P8: =V27/L4 -> 56.307692 | Q8: Note Brute de Cap
P9: =P7/((L8*5)-(L8*1))*100 -> 11.929279 | Q9: Note Brute de Cons
B10: Sondes | F10: 5 | K10: 10 | P10: 15 | U10: 20 | W10: Notes Standardises Par Element
A11: Elements | B11: a | C11: b | D11: c | E11: d | F11: e | G11: f | H11: g | I11: h | J11: i | K11: j | L11: k | M11: l | N11: m | O11: n | P11: o | Q11: p | R11: q | S11: r | T11: s | U11: t | V11: Som | W11: Note Cap | X11: Note Cons | Y11: Elements
A12: 1 | B12: 4 | C12: 4 | D12: 4 | E12: 4 | F12: 5 | G12: 3 | H12: 3 | I12: 4 | J12: 5 | K12: 4 | L12: 2 | M12: 4 | N12: 4 | V12: =SUM(B12:U12) -> 50 | W12: =V12/L4*20 -> 76.923077 | X12: =100-(AB39*2) -> 59.967962 | Y12: 1. Rapports aux bailleurs
A13: 2 | B13: 5 | C13: 4 | D13: 4 | E13: 4 | F13: 4 | G13: 4 | H13: 4 | I13: 4 | J13: 4 | K13: 3 | L13: 4 | M13: 2 | N13: 3 | V13: =SUM(B13:U13) -> 49 | W13: =V13/L4*20 -> 75.384615 | X13: =100-(AB40*2) -> 63.749447 | Y13: 2. Mobilisation de fonds
A14: 3 | B14: 5 | C14: 4 | D14: 4 | E14: 4 | F14: 4 | G14: 5 | H14: 3 | I14: 4 | J14: 5 | K14: 3 | L14: 3 | M14: 2 | N14: 2 | Q14: 0 | V14: =SUM(B14:U14) -> 48 | W14: =V14/L4*20 -> 73.846154 | X14: =100-(AB41*2) -> 48.422326 | Y14: 3. Relations publiques
A15: 4 | B15: 5 | C15: 4 | D15: 4 | E15: 4 | F15: 4 | G15: 4 | H15: 3 | I15: 4 | J15: 5 | K15: 4 | L15: 4 | M15: 4 | N15: 3 | V15: =SUM(B15:U15) -> 52 | W15: =V15/L4*20 -> 80 | X15: =100-(AB42*2) -> 71.132487 | Y15: 4. Plaidoyer
A16: 5 | B16: 5 | C16: 4 | D16: 4 | E16: 4 | F16: 4 | G16: 4 | H16: 3 | I16: 2 | J16: 5 | K16: 4 | L16: 2 | M16: 4 | N16: 4 | V16: =SUM(B16:U16) -> 49 | W16: =V16/L4*20 -> 75.384615 | X16: =100-(AB43*2) -> 53.659565 | Y16: 5. Contrôle financier
A17: 6 | B17: 5 | C17: 4 | D17: 4 | E17: 4 | F17: 5 | G17: 4 | H17: 4 | I17: 4 | J17: 4 | K17: 4 | L17: 2 | M17: 2 | N17: 2 | V17: =SUM(B17:U17) -> 48 | W17: =V17/L4*20 -> 73.846154 | X17: =100-(AB44*2) -> 48.422326 | Y17: 6. Définition de politiques
A18: 7 | B18: 5 | C18: 4 | D18: 4 | E18: 4 | F18: 4 | G18: 4 | H18: 5 | I18: 4 | J18: 5 | K18: 3 | L18: 2 | M18: 4 | N18: 4 | V18: =SUM(B18:U18) -> 52 | W18: =V18/L4*20 -> 80 | X18: =100-(AB45*2) -> 59.175171 | Y18: 7. Orientations stratégiques
A19: 8 | B19: 4 | C19: 4 | D19: 4 | E19: 4 | F19: 4 | G19: 3 | H19: 3 | I19: 4 | J19: 3 | K19: 3 | L19: 4 | M19: 2 | N19: 4 | V19: =SUM(B19:U19) -> 46 | W19: =V19/L4*20 -> 70.769231 | X19: =100-(AB46*2) -> 66.988735 | Y19: 8. Représentation selon bénéficiaires
A20: 9 | B20: 5 | C20: 3 | D20: 3 | E20: 4 | F20: 4 | G20: 4 | H20: 4 | I20: 4 | J20: 5 | K20: 3 | L20: 4 | M20: 4 | N20: 4 | V20: =SUM(B20:U20) -> 51 | W20: =V20/L4*20 -> 78.461538 | X20: =100-(AB47*2) -> 67.974369 | Y20: 9. Décisions du Conseil
A21: 10 | B21: 5 | C21: 4 | D21: 4 | E21: 5 | F21: 3 | G21: 4 | H21: 4 | I21: 5 | J21: 2 | K21: 4 | L21: 2 | M21: 3 | N21: 3 | V21: =SUM(B21:U21) -> 48 | W21: =V21/L4*20 -> 73.846154 | X21: =100-(AB48*2) -> 48.422326 | Y21: 10. Décisions du personnel
A22: 11 | B22: 5 | C22: 4 | D22: 4 | E22: 3 | F22: 4 | G22: 2 | H22: 4 | I22: 5 | J22: 2 | K22: 4 | L22: 3 | M22: 5 | N22: 2 | V22: =SUM(B22:U22) -> 47 | W22: =V22/L4*20 -> 72.307692 | X22: =100-(AB49*2) -> 43.955146 | Y22: 11. Personnel d’appoint
A23: 12 | B23: 5 | C23: 5 | D23: 5 | E23: 3 | F23: 4 | G23: 2 | H23: 4 | I23: 4 | J23: 4 | K23: 4 | L23: 4 | M23: 3 | N23: 4 | V23: =SUM(B23:U23) -> 51 | W23: =V23/L4*20 -> 78.461538 | X23: =100-(AB50*2) -> 56.884175 | Y23: 12. Environnement externe
A24: 13 | B24: 4 | C24: 4 | D24: 4 | E24: 4 | F24: 4 | G24: 2 | H24: 3 | I24: 4 | J24: 4 | K24: 3 | L24: 4 | M24: 2 | N24: 4 | V24: =SUM(B24:U24) -> 46 | W24: =V24/L4*20 -> 70.769231 | X24: =100-(AB51*2) -> 61.187499 | Y24: 13. Objectifs stratégiques
A25: 14 | B25: 4 | C25: 4 | D25: 4 | E25: 4 | F25: 4 | G25: 4 | H25: 3 | I25: 4 | J25: 5 | K25: 3 | L25: 4 | M25: 3 | N25: 4 | V25: =SUM(B25:U25) -> 50 | W25: =V25/L4*20 -> 76.923077 | X25: =100-(AB52*2) -> 72.26499 | Y25: 14. Initiatives conformes
A26: 15 | B26: 5 | C26: 4 | D26: 4 | E26: 3 | F26: 4 | G26: 4 | H26: 4 | I26: 4 | J26: 4 | K26: 3 | L26: 2 | M26: 2 | N26: 2 | V26: =SUM(B26:U26) -> 45 | W26: =V26/L4*20 -> 69.230769 | X26: =100-(AB53*2) -> 51.629104 | Y26: 15. Suivi régulier
A27: x | B27: =SUM(B12:B26) -> 71 | C27: =SUM(C12:C26) -> 60 | D27: =SUM(D12:D26) -> 60 | E27: =SUM(E12:E26) -> 58 | F27: =SUM(F12:F26) -> 61 | G27: =SUM(G12:G26) -> 53 | H27: =SUM(H12:H26) -> 54 | I27: =SUM(I12:I26) -> 60 | ... U27: =SUM(U12:U26) -> 0 | V27: =SUM(B27:U27) -> 732
A28: x2 | B28: =B27*B27 -> 5041 | C28: =C27*C27 -> 3600 | D28: =D27*D27 -> 3600 | E28: =E27*E27 -> 3364 | F28: =F27*F27 -> 3721 | G28: =G27*G27 -> 2809 | H28: =H27*H27 -> 2916 | I28: =I27*I27 -> 3600 | ... U28: =U27*U27 -> 0 | V28: =SUM(B28:U28) -> 41832 | W28: z*
A37: Fiche de Calcul pour la note distincte capacite (x2)
A38: Item | B38: a | C38: b | D38: c | E38: d | F38: e | G38: f | H38: g | I38: h | J38: i | K38: j | L38: k | M38: l | N38: m | O38: n | P38: o | Q38: p | R38: q | S38: r | T38: s | U38: t | V38: Som x2 | W38: y* | X38: n* | Y38: m | Z38: p | AA38: sd | AB38: brute
A39: 1 | B39: =B12*B12 -> 16 | C39: =C12*C12 -> 16 | D39: =D12*D12 -> 16 | E39: =E12*E12 -> 16 | F39: =F12*F12 -> 25 | G39: =G12*G12 -> 9 | H39: =H12*H12 -> 9 | I39: =I12*I12 -> 16 | ... U39: =U12*U12 -> 0 | V39: =SUM(B39:U39) -> 200 | W39: =V12*V12 -> 2500 | X39: =L4*(L4-1) -> 156 | Y39: =L4*V39-W39 -> 100 | Z39: =Y39/X39 -> 0.64102564 | AA39: =SQRT(Z39) -> 0.80064077 | AB39: =AA39/4*100 -> 20.016019
A40: 2 | B40: =B13*B13 -> 25 | C40: =C13*C13 -> 16 | D40: =D13*D13 -> 16 | E40: =E13*E13 -> 16 | F40: =F13*F13 -> 16 | G40: =G13*G13 -> 16 | H40: =H13*H13 -> 16 | I40: =I13*I13 -> 16 | ... U40: =U13*U13 -> 0 | V40: =SUM(B40:U40) -> 191 | W40: =V13*V13 -> 2401 | X40: =L4*(L4-1) -> 156 | Y40: =L4*V40-W40 -> 82 | Z40: =Y40/X40 -> 0.52564103 | AA40: =SQRT(Z40) -> 0.72501105 | AB40: =AA40/4*100 -> 18.125276
A41: 3 | B41: =B14*B14 -> 25 | C41: =C14*C14 -> 16 | D41: =D14*D14 -> 16 | E41: =E14*E14 -> 16 | F41: =F14*F14 -> 16 | G41: =G14*G14 -> 25 | H41: =H14*H14 -> 9 | I41: =I14*I14 -> 16 | ... U41: =U14*U14 -> 0 | V41: =SUM(B41:U41) -> 190 | W41: =V14*V14 -> 2304 | X41: =L4*(L4-1) -> 156 | Y41: =L4*V41-W41 -> 166 | Z41: =Y41/X41 -> 1.0641026 | AA41: =SQRT(Z41) -> 1.0315535 | AB41: =AA41/4*100 -> 25.788837
A42: 4 | B42: =B15*B15 -> 25 | C42: =C15*C15 -> 16 | D42: =D15*D15 -> 16 | E42: =E15*E15 -> 16 | F42: =F15*F15 -> 16 | G42: =G15*G15 -> 16 | H42: =H15*H15 -> 9 | I42: =I15*I15 -> 16 | ... U42: =U15*U15 -> 0 | V42: =SUM(B42:U42) -> 212 | W42: =V15*V15 -> 2704 | X42: =L4*(L4-1) -> 156 | Y42: =L4*V42-W42 -> 52 | Z42: =Y42/X42 -> 0.33333333 | AA42: =SQRT(Z42) -> 0.57735027 | AB42: =AA42/4*100 -> 14.433757
A43: 5 | B43: =B16*B16 -> 25 | C43: =C16*C16 -> 16 | D43: =D16*D16 -> 16 | E43: =E16*E16 -> 16 | F43: =F16*F16 -> 16 | G43: =G16*G16 -> 16 | H43: =H16*H16 -> 9 | I43: =I16*I16 -> 4 | ... U43: =U16*U16 -> 0 | V43: =SUM(B43:U43) -> 195 | W43: =V16*V16 -> 2401 | X43: =L4*(L4-1) -> 156 | Y43: =L4*V43-W43 -> 134 | Z43: =Y43/X43 -> 0.85897436 | AA43: =SQRT(Z43) -> 0.9268087 | AB43: =AA43/4*100 -> 23.170217
